Workbook

Sheet Copyright
A3: Product Number: | B3: 5B20N006
A4: Title: | B4: HDFC Bank: CAMELS Analysis and Discounted Cash Flow Valuation - Instructor Spreadsheet
B5: This spreadsheet supports the product "HDFC Bank: CAMELS Analysis and Discounted Cash Flow Valuation," product number 9B20N006.
A6: Prepared by: | B6: Vandana Gupta
A8: Last Revised: | B8: 43892
A10: No part of this file may be reproduced, stored in a retrieval system, posted to the Internet, or transmitted in any form or by any means without the permission of Ivey Business School Foundation. To order copies or request permission to reproduce materials, contact Ivey Publishing, Ivey Business School, Western University, London, Ontario, Canada, N6G 0N1; (t) 519.661.3208; (e) cases@ivey.ca; www.iveycases.com. Our goal is to publish materials of the highest quality; submit any errata to publishcases@ivey.ca.
A12: © 2020 Ivey Business School Foundation

Sheet Main
C1: Higher the Better
C2: Lower the Better
A3: CAMELS MODEL
A5: Actual Values (Table 1 )
A6: Bank Name | B6: Capital Adequacy | E6: Asset Quality | H6: Management Quality | K6: Earning Ability | O6: Liquidity | R6: Sensivity to Market Risk
B7: Higher is Better | C7: Lower is Better | D7: Higher is Better | E7: Lower is Better | F7: Higher is Better | G7: Higher is Better | H7: Higher is Better | I7: Higher is Better | J7: Higher is Better | K7: Higher is Better | L7: Higher is Better | M7: Higher is Better | N7: Lower is Better | O7: Higher is Better | P7: Higher is Better | Q7: Higher is Better | R7: Lower is better
B8: CRAR | C8: D/E | D8: Coverage | E8: NPA/Net Advances | F8: G-Sec/ Investments | G8: Standard Advances/Total Advance Ratio | H8: Profit Per Emp | I8: Total Advances/Total Deposits | J8: Busisness Per Employee | K8: ROA | L8: Income Spread/Total Asset | M8: Operating Profit /Total Asset | N8: Operating expenses by Net Inc | O8: Cash Asset/Total Asset | P8: G-Sec/Total Asset | Q8: Liquid Asset/ Total Asset Ratio | R8: Beta (5-yr monthly) Source: Thomson Reuters
A9: HDFC Bank | B9: 0.148 | C9: 1.5024 | D9: =HDFC!A9 -> 0.1138683 | E9: =HDFC!A1 -> 0.004 | F9: =HDFC!A12 -> 0.77772343 | G9: =HDFC!A16 -> 0.987 | H9: =HDFC!A23 -> 1987128.2 | I9: =HDFC!A18 -> 0.83463184 | J9: =HDFC!A22 -> 1.6444361e+08 | K9: =HDFC!A25 -> 0.01643591 | L9: =HDFC!A29 -> 0.037685469 | M9: =HDFC!A31 -> 0.030664308 | N9: =HDFC!A33 -> 1.2975761 | O9: =HDFC!A35 -> 0.098380577 | P9: =HDFC!A36 -> 0.17704552 | Q9: =HDFC!A39 -> 0.15583121 | R9: 0.98548305
A10: Yes Bank | B10: 0.184 | C10: 2.9437 | D10: =Yes!A9 -> 0.091792704 | E10: =Yes!A1 -> 0.0064 | F10: =Yes!A12 -> 0.71975743 | G10: =Yes!A16 -> 0.9872 | H10: =Yes!A23 -> 2316352.5 | I10: =Yes!A18 -> 1.0139272 | J10: =Yes!A22 -> 2.2166466e+08 | K10: =Yes!A25 -> 0.013520957 | L10: =Yes!A29 -> 0.0247629 | M10: =Yes!A31 -> 0.024798278 | N10: =Yes!A33 -> 1.2339215 | O10: =Yes!A35 -> 0.036568762 | P10: =Yes!A36 -> 0.15756549 | Q10: =Yes!A39 -> 0.12321707 | R10: 1.88
A11: ICICI Bank | B11: 0.1842 | C11: 2.1397 | D11: =ICICI!A9 -> 0.095593523 | E11: =ICICI!A1 -> 0.054422827 | F11: =ICICI!A12 -> 0.69722694 | G11: =ICICI!A16 -> 0.89448966 | H11: =ICICI!A23 -> 831096.15 | I11: =ICICI!A18 -> 0.91340095 | J11: =ICICI!A22 -> 1.3162438e+08 | K11: =ICICI!A25 -> 0.0077087198 | L11: =ICICI!A29 -> 0.026189866 | M11: =ICICI!A31 -> 0.021541439 | N11: =ICICI!A33 -> 2.3171049 | O11: =ICICI!A35 -> 0.037651035 | P11: =ICICI!A36 -> 0.1609813 | Q11: =ICICI!A39 -> 0.15004118 | R11: 1.4703467
A12: Axis Bank | B12: 0.1657 | C12: 2.5026 | D12: ='Axis Bank'!A9 -> 0.070549318 | E12: ='Axis Bank'!A1 -> 0.034 | F12: ='Axis Bank'!A12 -> 0.67621284 | G12: ='Axis Bank'!A16 -> 0.9323 | H12: ='Axis Bank'!A23 -> 46255.252 | I12: ='Axis Bank'!A18 -> 0.96919815 | J12: ='Axis Bank'!A22 -> 1.4987802e+08 | K12: ='Axis Bank'!A25 -> 0.00039876972 | L12: ='Axis Bank'!A29 -> 0.026930325 | M12: ='Axis Bank'!A31 -> 0.022556535 | N12: ='Axis Bank'!A33 -> 50.748237 | O12: ='Axis Bank'!A35 -> 0.051322927 | P12: ='Axis Bank'!A36 -> 0.1505114 | Q12: ='Axis Bank'!A39 -> 0.095795225 | R12: 1.4468212
A13: State Bank of India | B13: 0.126 | C13: 1.7182 | D13: =SBI!A9 -> 0.029441324 | E13: =SBI!A1 -> 0.0573 | F13: =SBI!A12 -> 0.80954482 | G13: =SBI!A16 -> 0.8909 | H13: =SBI!A23 -> -241603.46 | I13: =SBI!A18 -> 0.71494263 | J13: =SBI!A22 -> 1.7126286e+08 | K13: =SBI!A25 -> -0.0018952022 | L13: =SBI!A29 -> 0.021666885 | M13: =SBI!A31 -> 0.017225824 | N13: =SBI!A33 -> -9.1552303 | O13: =SBI!A35 -> 0.043533423 | P13: =SBI!A36 -> 0.2486188 | Q13: =SBI!A39 -> 0.070906985 | R13: 1.6802277
A14: Weights | B14: 0.7 | C14: 0.15 | D14: =1-B14-C14 -> 0.15 | E14: 0.1 | F14: 0.3 | G14: =1-E14-F14 -> 0.6 | H14: 0.5 | I14: 0.25 | J14: =1-H14-I14 -> 0.25 | K14: 0.0025 | L14: 0.25 | M14: 0.25 | N14: 0.0025 | O14: 0.25 | P14: 0.25 | Q14: =1-O14-P14 -> 0.5 | R14: 1
A15: Composite Weights | B15: 0.2 | E15: 0.2 | H15: 0.2 | K15: 0.2 | O15: 0.1 | R15: 0.1
A16: Composite Index: Ratio Wise (Table 2)
B17: CRAR | C17: D/E | D17: Coverage | E17: NPA/Net Advances | F17: G-Sec/ Investments | G17: Standard Advances/Total Advance Ratio | H17: Profit Per Emp | I17: Total Advances/Total Deposits | J17: Busisness Per Employee | K17: ROA | L17: Income Spread/Total Asset | M17: Operating Profit /Total Asset | N17: Operating expenses by Net Inc | O17: Cash Asset/Total Asset | P17: G-Sec/Total Asset | Q17: Liquid Asset/ Total Asset Ratio | R17: =R8 -> Beta (5-yr monthly) Source: Thomson Reuters
A18: HDFC Bank | B18: =(B9-$B$13)/($B$11-$B$13) -> 0.37800687 | C18: =(C$10-C9)/($C$10-$C$9) -> 1 | D18: =(D9-$D$13)/($D$9-$D$13) -> 1 | E18: =($E$13-E9)/($E$13-$E$9) -> 1 | F18: =(F9-$F$12)/($F$13-$F$12) -> 0.76133716 | G18: =(G9-$G$13)/($G$10-$G$13) -> 0.99792316 | H18: =(H9-$H$13)/($H$10-$H$13) -> 0.871294 | I18: =(I9-$I$13)/($I$10-$I$13) -> 0.40031905 | J18: =(J9-$J$11)/($J$10-$J$11) -> 0.36449492 | K18: =(K9-$K$13)/($K$9-$K$13) -> 1 | L18: =(L9-$L$13)/($L$9-$L$13) -> 1 | M18: =(M9-$M$13)/($M$9-$M$13) -> 1 | N18: =($N$12-N9)/($N$12-$N$13) -> 0.82550582 | O18: =(O9-$O$10)/($O$9-$O$10) -> 1 | P18: =(P9-$P$12)/($P$13-$P$12) -> 0.2704599 | Q18: =(Q9-$Q$13)/($Q$9-$Q$13) -> 1 | R18: =($R$10-R9)/($R$10-$R$9) -> 1
A19: Yes Bank | B19: =(B10-$B$13)/($B$11-$B$13) -> 0.99656357 | C19: =(C$10-C10)/($C$10-$C$9) -> 0 | D19: =(D10-$D$13)/($D$9-$D$13) -> 0.73852439 | E19: =($E$13-E10)/($E$13-$E$9) -> 0.95497186 | F19: =(F10-$F$12)/($F$13-$F$12) -> 0.32658773 | G19: =(G10-$G$13)/($G$10-$G$13) -> 1 | H19: =(H10-$H$13)/($H$10-$H$13) -> 1 | I19: =(I10-$I$13)/($I$10-$I$13) -> 1 | J19: =(J10-$J$11)/($J$10-$J$11) -> 1 | K19: =(K10-$K$13)/($K$9-$K$13) -> 0.84098334 | L19: =(L10-$L$13)/($L$9-$L$13) -> 0.19327642 | M19: =(M10-$M$13)/($M$9-$M$13) -> 0.5634902 | N19: =($N$12-N10)/($N$12-$N$13) -> 0.82656844 | O19: =(O10-$O$10)/($O$9-$O$10) -> 0 | P19: =(P10-$P$12)/($P$13-$P$12) -> 0.071901701 | Q19: =(Q10-$Q$13)/($Q$9-$Q$13) -> 0.61596188 | R19: =($R$10-R10)/($R$10-$R$9) -> 0
A20: ICICI Bank | B20: =(B11-$B$13)/($B$11-$B$13) -> 1 | C20: =(C$10-C11)/($C$10-$C$9) -> 0.55782974 | D20: =(D11-$D$13)/($D$9-$D$13) -> 0.7835434 | E20: =($E$13-E11)/($E$13-$E$9) -> 0.053980731 | F20: =(F11-$F$12)/($F$13-$F$12) -> 0.15760732 | G20: =(G11-$G$13)/($G$10-$G$13) -> 0.037275821 | H20: =(H11-$H$13)/($H$10-$H$13) -> 0.41935812 | I20: =(I11-$I$13)/($I$10-$I$13) -> 0.66377449 | J20: =(J11-$J$11)/($J$10-$J$11) -> 0 | K20: =(K11-$K$13)/($K$9-$K$13) -> 0.52391378 | L20: =(L11-$L$13)/($L$9-$L$13) -> 0.28235831 | M20: =(M11-$M$13)/($M$9-$M$13) -> 0.32113855 | N20: =($N$12-N11)/($N$12-$N$13) -> 0.80848629 | O20: =(O11-$O$10)/($O$9-$O$10) -> 0.017509157 | P20: =(P11-$P$12)/($P$13-$P$12) -> 0.10671872 | Q20: =(Q11-$Q$13)/($Q$9-$Q$13) -> 0.9318212 | R20: =($R$10-R11)/($R$10-$R$9) -> 0.45796032
A21: Axis Bank | B21: =(B12-$B$13)/($B$11-$B$13) -> 0.68213058 | C21: =(C$10-C12)/($C$10-$C$9) -> 0.30604316 | D21: =(D12-$D$13)/($D$9-$D$13) -> 0.48690593 | E21: =($E$13-E12)/($E$13-$E$9) -> 0.43714822 | F21: =(F12-$F$12)/($F$13-$F$12) -> 0 | G21: =(G12-$G$13)/($G$10-$G$13) -> 0.42990654 | H21: =(H12-$H$13)/($H$10-$H$13) -> 0.11253466 | I21: =(I12-$I$13)/($I$10-$I$13) -> 0.85039688 | J21: =(J12-$J$11)/($J$10-$J$11) -> 0.20272754 | K21: =(K12-$K$13)/($K$9-$K$13) -> 0.12514091 | L21: =(L12-$L$13)/($L$9-$L$13) -> 0.32858336 | M21: =(M12-$M$13)/($M$9-$M$13) -> 0.39667503 | N21: =($N$12-N12)/($N$12-$N$13) -> 0 | O21: =(O12-$O$10)/($O$9-$O$10) -> 0.2386949 | P21: =(P12-$P$12)/($P$13-$P$12) -> 0 | Q21: =(Q12-$Q$13)/($Q$9-$Q$13) -> 0.29306408 | R21: =($R$10-R12)/($R$10-$R$9) -> 0.48426004
A22: Staet Bank of India | B22: =(B13-$B$13)/($B$11-$B$13) -> 0 | C22: =(C$10-C13)/($C$10-$C$9) -> 0.85027406 | D22: =(D13-$D$13)/($D$9-$D$13) -> 0 | E22: =($E$13-E13)/($E$13-$E$9) -> 0 | F22: =(F13-$F$12)/($F$13-$F$12) -> 1 | G22: =(G13-$G$13)/($G$10-$G$13) -> 0 | H22: =(H13-$H$13)/($H$10-$H$13) -> 0 | I22: =(I13-$I$13)/($I$10-$I$13) -> 0 | J22: =(J13-$J$11)/($J$10-$J$11) -> 0.44023051 | K22: =(K13-$K$13)/($K$9-$K$13) -> 0 | L22: =(L13-$L$13)/($L$9-$L$13) -> 0 | M22: =(M13-$M$13)/($M$9-$M$13) -> 0 | N22: =($N$12-N13)/($N$12-$N$13) -> 1 | O22: =(O13-$O$10)/($O$9-$O$10) -> 0.11267524 | P22: =(P13-$P$12)/($P$13-$P$12) -> 1 | Q22: =(Q13-$Q$13)/($Q$9-$Q$13) -> 0 | R22: =($R$10-R13)/($R$10-$R$9) -> 0.22332976
A24: Composite Index: CAMELS (Table 3)
B25: Capital Adequacy | E25: Asset Quality | H25: Management Quality | K25: Earning Ability | O25: Liquidity | R25: Sensitivity To Market Risk
A26: HDFC Bank | B26: =($B$14*B18)+($C$14*C18)+($D$14*D18) -> 0.56460481 | E26: =($E$14*E18)+($F$14*F18)+($G$14*G18) -> 0.92715504 | H26: =($H$14*H18)+($I$14*I18)+($J$14*J18) -> 0.62685049 | K26: =($K$14*K18)+($L$14*L18)+($M$14*M18)+($N$14*N18) -> 0.50456376 | O26: =($O$14*O18)+($P$14*P18)+($Q$14*Q18) -> 0.81761498 | R26: =R18*$R$14 -> 1
A27: Yes Bank | B27: =($B$14*B19)+($C$14*C19)+($D$14*D19) -> 0.80837316 | E27: =($E$14*E19)+($F$14*F19)+($G$14*G19) -> 0.7934735 | H27: =($H$14*H19)+($I$14*I19)+($J$14*J19) -> 1 | K27: =($K$14*K19)+($L$14*L19)+($M$14*M19)+($N$14*N19) -> 0.19336054 | O27: =($O$14*O19)+($P$14*P19)+($Q$14*Q19) -> 0.32595637 | R27: =R19*$R$14 -> 0
A28: ICICI Bank | B28: =($B$14*B20)+($C$14*C20)+($D$14*D20) -> 0.90120597 | E28: =($E$14*E20)+($F$14*F20)+($G$14*G20) -> 0.07504576 | H28: =($H$14*H20)+($I$14*I20)+($J$14*J20) -> 0.37562268 | K28: =($K$14*K20)+($L$14*L20)+($M$14*M20)+($N$14*N20) -> 0.15420522 | O28: =($O$14*O20)+($P$14*P20)+($Q$14*Q20) -> 0.49696757 | R28: =R20*$R$14 -> 0.45796032
A29: Axis Bank | B29: =($B$14*B21)+($C$14*C21)+($D$14*D21) -> 0.59643377 | E29: =($E$14*E21)+($F$14*F21)+($G$14*G21) -> 0.30165875 | H29: =($H$14*H21)+($I$14*I21)+($J$14*J21) -> 0.31954843 | K29: =($K$14*K21)+($L$14*L21)+($M$14*M21)+($N$14*N21) -> 0.18162745 | O29: =($O$14*O21)+($P$14*P21)+($Q$14*Q21) -> 0.20620577 | R29: =R21*$R$14 -> 0.48426004
A30: State Bank of India | B30: =($B$14*B22)+($C$14*C22)+($D$14*D22) -> 0.12754111 | E30: =($E$14*E22)+($F$14*F22)+($G$14*G22) -> 0.3 | H30: =($H$14*H22)+($I$14*I22)+($J$14*J22) -> 0.11005763 | K30: =($K$14*K22)+($L$14*L22)+($M$14*M22)+($N$14*N22) -> 0.0025 | O30: =($O$14*O22)+($P$14*P22)+($Q$14*Q22) -> 0.27816881 | R30: =R22*$R$14 -> 0.22332976
A31: Table 4
B32: CAMELS Score
A33: HDFC Bank | B33: =($B$15*B26)+($E$15*E26)+($H$15*H26)+($K$15*K26)+($O$15*O26)+(R26*$R$15) -> 0.70639632
A34: Yes Bank | B34: =($B$15*B27)+($E$15*E27)+($H$15*H27)+($K$15*K27)+($O$15*O27)+(R27*$R$15) -> 0.59163708
A35: ICICI Bank | B35: =($B$15*B28)+($E$15*E28)+($H$15*H28)+($K$15*K28)+($O$15*O28)+(R28*$R$15) -> 0.39670872
A36: Axis Bank | B36: =($B$15*B29)+($E$15*E29)+($H$15*H29)+($K$15*K29)+($O$15*O29)+(R29*$R$15) -> 0.34890026
A37: State Bank of India | B37: =($B$15*B30)+($E$15*E30)+($H$15*H30)+($K$15*K30)+($O$15*O30)+(R30*$R$15) -> 0.1581696
A39: Source: Created by the case author using the framework explained in the case.

Sheet HDFC
A1: 0.004 | B1: Net NPA by Net Advances
A2: =A13 -> 6583330908000 | B2: =B13 -> Total Advances
A3: =A1*A2 -> 26333323632 | B3: NPA
A4: 5190181000 | B4: Capital
A5: 1057759776000 | B5: Reserves and Surplus
A6: =A20 -> 174867283000 | B6: =B20 -> PAT
A7: =A4+A5+A6 -> 1237817240000 | B7: Net Worth
A8: =A7-A3 -> 1211483916368 | B8: Net Worth - NPA
A9: =A8/A24 -> 0.1138683 | B9: Coverage
A10: 1883648036000 | B10: G-Sec
A11: 2422002416000 | B11: TI
A12: =A10/A11 -> 0.77772343 | B12: G-Sec/TI
A13: 6583330908000 | B13: Total Advances
A14: =0.013*A13 -> 85583301804 | B14: Gross NPA
A15: =A13-A14 -> 6497747606196 | B15: Net of Gross NPA to TA
A16: =A15/A13 -> 0.987 | B16: Standard Advances/ Total Advance Ratio
A17: 7887706396000 | B17: Total Depoists
A18: =A13/A17 -> 0.83463184 | B18: Total Advances By Total Deposists
A19: 88000 | B19: No. of Employees
A20: 174867283000 | B20: PAT
A21: =A13+A17 -> 14471037304000 | B21: Businees (TA+TD)
A22: =A21/A19 -> 1.6444361e+08 | B22: Business per Emp
A23: =A20/A19 -> 1987128.2 | B23: Profit per Emp
A24: 10639343234000 | B24: Total Assets
A25: =A20/A24 -> 0.01643591 | B25: ROA
A26: 802413550000 | B26: Interest Earned
A27: 401464913000 | B27: Interest Expended
A28: =A26-A27 -> 400948637000 | B28: Spread
A29: =A28/A24 -> 0.037685469 | B29: Spread by Total Assets
A30: 326248100000 | B30: Operating Profit
A31: =A30/A24 -> 0.030664308 | B31: Operating Profit/Total Assets
A32: 226903600000 | B32: Operating Expenses
A33: =A32/A20 -> 1.2975761 | B33: Operating Expenses by NI
A34: 1046704730000 | B34: Cash Assets
A35: =A34/A24 -> 0.098380577 | B35: Cash Assets by Total Assets
A36: =A10/A24 -> 0.17704552 | B36: G-Sec/Total Asset
A37: 182446097000 | B37: Balance at Short Notice
A38: =A34+A37 -> 1229150827000 | B38: Liquid Asset
A39: =A38/A17 -> 0.15583121 | B39: Liquid Asset / TD Ratio
A41: Source: HDFC Bank Ltd., Experiential Leadership: Enabling Personalized Customer Journeys through Technology, Annual Report 2017–18, accessed September 30, 2018, www.hdfcbank.com/htdocs/common/pdf/corporate/Annual_Report_2017_18.pdf

Sheet Yes
A1: 0.0064 | B1: Net NPA by Net Advances
A2: =A13 -> 2035338628000 | B2: =B13 -> Total Advances
A3: =A1*A2 -> 1.3026167e+10 | B3: NPA
A4: 4605934000 | B4: Capital
A5: 252976864000 | B5: Reserves & Surplus
A6: =A20 -> 42245637000 | B6: =B20 -> PAT
A7: =A4+A5+A6 -> 299828435000 | B7: Net Worth
A8: =A7-A3 -> 2.8680227e+11 | B8: Net Worth - NPA
A9: =A8/A24 -> 0.091792704 | B9: Coverage
A10: =488860831000+3445612000 -> 492306443000 | B10: G-Sec
A11: 683989387000 | B11: TI
A12: =A10/A11 -> 0.71975743 | B12: G-Sec/TI
A13: 2035338628000 | B13: Total Advances
A14: =0.0128*A13 -> 2.6052334e+10 | B14: Gross NPA
A15: =A13-A14 -> 2.0092863e+12 | B15: Net of Gross NPA to TA
A16: =A15/A13 -> 0.9872 | B16: Standard Advances/Total Advance Ratio
A17: 2007381476000 | B17: Total Depoists
A18: =A13/A17 -> 1.0139272 | B18: Total Advances By Total Deposists
A19: 18238 | B19: Number of Employees
A20: 42245637000 | B20: PAT
A21: =A13+A17 -> 4042720104000 | B21: Businees (TA+TD)
A22: =A21/A19 -> 2.2166466e+08 | B22: Business per Emp
A23: =A20/A19 -> 2316352.5 | B23: Profit per Emp
A24: 3124456033000 | B24: Total Assets
A25: =A20/A24 -> 0.013520957 | B25: ROA
A26: 202674216000 | B26: Interest Earned
A27: 125303624000 | B27: Interest Expended
A28: =A26-A27 -> 77370592000 | B28: Spread
A29: =A28/A24 -> 0.0247629 | B29: Spread by Total Assets
A30: 77481130000 | B30: Operating Profit
A31: =A30/A24 -> 0.024798278 | B31: Operating Profit/Total Assets
A32: 52127800000 | B32: Operating Expenses
A33: =A32/A20 -> 1.2339215 | B33: Operating Expenses by NI
A34: 114257489000 | B34: Cash Assets
A35: =A34/A24 -> 0.036568762 | B35: Cash Assets by Total Assets
A36: =A10/A24 -> 0.15756549 | B36: G-Sec/Total Asset
A37: 133086175000 | B37: Balance at Short Notice
A38: =A34+A37 -> 247343664000 | B38: Liquid Asset
A39: =A38/A17 -> 0.12321707 | B39: Liquid Asset/TD Ratio
A41: Source: Annual Report of Yes Bank Ltd., accessed on October 3, 2018, www.yesbank.in/pdf/annualreport_2017_18_pdf.

Sheet ICICI
A1: =A3/A2 -> 0.054422827 | B1: Net NPA by Net Advances
A2: =A13 -> 5123952856000 | B2: =B13 -> Total Advances
A3: 278860000000 | B3: NPA
A4: 12858100000 | B4: Capital
A5: 1038675565000 | B5: Reserves and Surplus
A6: =A20 -> 67774229000 | B6: =B20 -> PAT
A7: =A4+A5+A6 -> 1119307894000 | B7: Net Worth
A8: =A7-A3 -> 840447894000 | B8: Networth - NPA
A9: =A8/A24 -> 0.095593523 | B9: Coverage
A10: =1391852905000+23477202000 -> 1415330107000 | B10: G-sec
A11: 2029941808000 | B11: TI
A12: =A10/A11 -> 0.69722694 | B12: G-sec/TI
A13: 5123952856000 | B13: Total Advances
A14: 540630000000 | B14: Gross NPA | E14: 540630000000
A15: =A13-A14 -> 4583322856000 | B15: Net of Gross NPA to TA
A16: =A15/A13 -> 0.89448966 | B16: Standard Advances/ Total Advance Ratio
A17: 5609752085000 | B17: Total Depoists
A18: =A13/A17 -> 0.91340095 | B18: Total Advances By Total Deposists
A19: 81548 | B19: Number of Employees
A20: 67774229000 | B20: PAT
A21: =A13+A17 -> 10733704941000 | B21: Businees (TA+TD)
A22: =A21/A19 -> 1.3162438e+08 | B22: Business Per Emp
A23: =A20/A19 -> 831096.15 | B23: Profit Per Emp
A24: 8791891613000 | B24: Total Assets
A25: =A20/A24 -> 0.0077087198 | B25: ROA
A26: 549658922000 | B26: Interest earned
A27: 319400463000 | B27: Interest Expended
A28: =A26-A27 -> 230258459000 | B28: Spread
A29: =A28/A24 -> 0.026189866 | B29: Spread by Total Assets
A30: 189390000000 | B30: Operating Profit
A31: =A30/A24 -> 0.021541439 | B31: Operating Profit/Total Assets
A32: 157040000000 | B32: Operating Expenses
A33: =A32/A20 -> 2.3171049 | B33: Operating Expenses by NI
A34: 331023817000 | B34: Cash Assets
A35: =A34/A24 -> 0.037651035 | B35: Cash Assets by Total Assets
A36: =A10/A24 -> 0.1609813 | B36: G-sec/Total Asset
A37: 510669991000 | B37: Balance at Short Notice
A38: =A34+A37 -> 841693808000 | B38: Liquid Asset
A39: =A38/A17 -> 0.15004118 | B39: Liquid Asset / TD Ratio
A41: Source: Annual Report of ICICI Bank Limited, accessed on October 3, 2018, www.icicibank.com/managed-assets/docs/investor/annual-reports/2018/annual-report-fy2018.pdf.

Sheet Axis Bank
A1: 0.034 | B1: Net NPA by Net Advances
A2: =A13 -> 4396503045000 | B2: =B13 -> Total Advances
A3: =A2*A1 -> 149481103530 | B3: NPA
A4: 5133078000 | B4: Capital
A5: 629319518000 | B5: Reserves & Surplus
A6: =A20 -> 2756813000 | B6: =B20 -> PAT
A7: =A4+A5+A6 -> 637209409000 | B7: Net Worth
A8: =A7-A3 -> 487728305470 | B8: Networth - NPA
A9: =A8/A24 -> 0.070549318 | B9: Coverage
A10: =1013545679000+26984150000 -> 1040529829000 | B10: Gsec
A11: 1538760827000 | B11: TI
A12: =A10/A11 -> 0.67621284 | B12: Gsec/TI
A13: 4396503045000 | B13: Total Advances
A14: =0.0677*A13 -> 2.9764326e+11 | B14: Gross NPA | E14: 540630000000
A15: =A13-A14 -> 4.0988598e+12 | B15: Net of Gross NPA to TA
A16: =A15/A13 -> 0.9323 | B16: Standard Advances/ Total Advance Ratio
A17: 4536227223000 | B17: Total Depoists
A18: =A13/A17 -> 0.96919815 | B18: Total Advances By Total Deposists
A19: 59600 | B19: No. of Employees
A20: 2756813000 | B20: PAT
A21: =A13+A17 -> 8932730268000 | B21: Businees (TA+TD) | H21: 0.0677
A22: =A21/A19 -> 1.4987802e+08 | B22: Business Per Emp
A23: =A20/A19 -> 46255.252 | B23: Profit Per Emp
A24: 6913295799000 | B24: Total Assets
A25: =A20/A24 -> 0.00039876972 | B25: ROA
A26: 457803123000 | B26: Interest earned
A27: 271625818000 | B27: Interest Expended
A28: =A26-A27 -> 186177305000 | B28: Spread
A29: =A28/A24 -> 0.026930325 | B29: Spread by Total Assets
A30: 155940000000 | B30: Operating Profit
A31: =A30/A24 -> 0.022556535 | B31: Operating Profit/Total Assets
A32: 139903400000 | B32: Operating Expenses
A33: =A32/A20 -> 50.748237 | B33: Operating Expenses by NI
A34: 354810577000 | B34: Cash Assets
A35: =A34/A24 -> 0.051322927 | B35: Cash Assets by Total Assets
A36: =A10/A24 -> 0.1505114 | B36: Gsec/Total Asset
A37: 79738329000 | B37: Balance at Short Notice
A38: =A34+A37 -> 434548906000 | B38: Liquid Asset
A39: =A38/A17 -> 0.095795225 | B39: Liquid Asset / TD Ratio
A41: Source: Annual Report Axis Bank Limited, accessed on October 3, 2018, www.axisbank.com/docs/default-source/annual-reports/for-axis-bank/annual-report-for-the-year-2017-2018.pdf.

Sheet SBI
A1: 0.0573 | B1: Net NPA by Net Advances
A2: =A13 -> 19348801891000 | B2: =B13 -> Total Advances
A3: =A2*A1 -> 1.1086863e+12 | B3: NPA
A4: 8924588000 | B4: Capital
A5: 2182361015000 | B5: Reserves and Surplus
A6: =A20 -> -65474537000 | B6: =B20 -> PAT
A7: =A4+A5+A6 -> 2125811066000 | B7: Net Worth
A8: =A7-A3 -> 1.0171247e+12 | B8: Networth - NPA
A9: =A8/A24 -> 0.029441324 | B9: Coverage
A10: =8483958444000+105204585000 -> 8589163029000 | B10: G-sec
A11: 10609867150000 | B11: TI
A12: =A10/A11 -> 0.80954482 | B12: G-sec/TI
A13: 19348801891000 | B13: Total Advances
A14: =0.1091*A13 -> 2.1109543e+12 | B14: Gross NPA
A15: =A13-A14 -> 1.7237848e+13 | B15: Net of Gross NPA to TA
A16: =A15/A13 -> 0.8909 | B16: Standard Advances/ Total Advance Ratio
A17: 27063432850000 | B17: Total Depoists
A18: =A13/A17 -> 0.71494263 | B18: Total Advances By Total Deposists
A19: 271000 | B19: No. of Employees
A20: -65474537000 | B20: PAT
A21: =A13+A17 -> 46412234741000 | B21: Businees (TA + TD)
A22: =A21/A19 -> 1.7126286e+08 | B22: Business Per Emp
A23: =A20/A19 -> -241603.46 | B23: Profit Per Emp
A24: 34547519966000 | B24: Total Assets
A25: =A20/A24 -> -0.0018952022 | B25: ROA
A26: 2204993156000 | B26: Interest earned
A27: 1456456000000 | B27: Interest Expended
A28: =A26-A27 -> 748537156000 | B28: Spread
A29: =A28/A24 -> 0.021666885 | B29: Spread by Total Assets
A30: 595109500000 | B30: Operating Profit
A31: =A30/A24 -> 0.017225824 | B31: Operating Profit/Total Assets
A32: 599434464000 | B32: Operating Expenses
A33: =(A32/A20) -> -9.1552303 | B33: Operating Expenses by NI
A34: 1503971814000 | B34: Cash Assets
A35: =A34/A24 -> 0.043533423 | B35: Cash Assets by Total Assets
A36: =A10/A24 -> 0.2486188 | B36: G-sec/Total Asset
A37: 415014605000 | B37: Balance at Short Notice
A38: =A34+A37 -> 1918986419000 | B38: Liquid Asset
A39: =A38/A17 -> 0.070906985 | B39: Liquid Asset / TD Ratio
A41: Source: Annual Report State Bank of India Limited, accessed on October 3, 2018, www.sbigroup.co.jp/english/investors/library/annualreport/pdf/2018ar_e-042-103.pdf.

Sheet Ratio Analysis
A1: Bank Name | B1: Capital Adequacy | E1: Asset Quality | H1: Management Quality | K1: Earning Ability | O1: Liquidity | R1: Sensivity to Market Risk
B2: Higher is Better | C2: Lower is Better | D2: Higher is Better | E2: Lower is Better | F2: Higher is Better | G2: Higher is Better | H2: Higher is Better | I2: Higher is Better | J2: Higher is Better | K2: Higher is Better | L2: Higher is Better | M2: Higher is Better | N2: Lower is Better | O2: Higher is Better | P2: Higher is Better | Q2: Higher is Better | R2: Lower is better
B3: CRAR | C3: D/E | D3: Coverage | E3: NPA/Net Advances | F3: G-sec/ Investments | G3: Standard Advances/Total Advance Ratio | H3: Profit Per Emp | I3: Total Advances/Total Deposits | J3: Busisness Per Employee | K3: ROA | L3: Income Spread/Total Asset | M3: Operating Profit /Total Asset | N3: Operating Expenses by Net Inc | O3: Cash Asset/Total Asset | P3: G-Sec/Total Asset | Q3: Liquid Asset/ Total Asset Ratio | R3: Beta (5-yr monthly) Source: Thomson Reuters
A4: HDFC Bank | B4: 0.148 | C4: 1.5024 | D4: 0.1139 | E4: 0.004 | F4: 0.7777 | G4: 0.987 | H4: 1987128.2 | I4: 0.83 | J4: 1.6444361e+08 | K4: 0.0164 | L4: 0.03769 | M4: 0.0307 | N4: 1.3 | O4: 0.1 | P4: 0.18 | Q4: 0.16 | R4: 0.99
A5: Yes Bank | B5: 0.184 | C5: 2.9437 | D5: 0.0918 | E5: 0.0064 | F5: 0.7198 | G5: 0.9872 | H5: 2316352.5 | I5: 1.01 | J5: 2.2166466e+08 | K5: 0.0135 | L5: 0.02476 | M5: 0.02 | N5: 1.23 | O5: 0.04 | P5: 0.16 | Q5: 0.12 | R5: 1.88
A6: ICICI Bank | B6: 0.1842 | C6: 2.1397 | D6: 0.0956 | E6: 0.05442 | F6: 0.6972 | G6: 0.8945 | H6: 831096.15 | I6: 0.91 | J6: 1.3162438e+08 | K6: 0.0077 | L6: 0.02619 | M6: 0.02 | N6: 2.32 | O6: 0.04 | P6: 0.16 | Q6: 0.15 | R6: 1.47
A7: Axis Bank | B7: 0.1657 | C7: 2.5026 | D7: 0.0705 | E7: 0.034 | F7: 0.6762 | G7: 0.9323 | H7: 46255.25 | I7: 0.97 | J7: 1.4987802e+08 | K7: 0.0004 | L7: 0.02693 | M7: 0.02 | N7: 50.75 | O7: 0.05 | P7: 0.15 | Q7: 0.1 | R7: 1.45
A8: SBI | B8: 0.126 | C8: 1.7182 | D8: 0.0294 | E8: 0.0573 | F8: 0.8095 | G8: 0.8909 | H8: -241603.46 | I8: 0.71 | J8: 1.7126286e+08 | K8: -0.0019 | L8: 0.02167 | M8: 0.02 | N8: -9.16 | O8: 0.04 | P8: 0.25 | Q8: 0.07 | R8: 1.68
A9: Weights | B9: 0.7 | C9: 0.15 | D9: 0.15 | E9: 0.1 | F9: 0.3 | G9: 0.6 | H9: 0.5 | I9: 0.25 | J9: 0.25 | K9: 0.0025 | L9: 0.25 | M9: 0.25 | N9: 0.0025 | O9: 0.25 | P9: 0.25 | Q9: 0.5 | R9: 1
A10: Composite Weights | B10: 0.2 | E10: 0.2 | H10: 0.2 | K10: 0.2 | O10: 0.1 | R10: 0.1
A12: Bank Name | B12: Earning Ability | F12: Liquidity | I12: Sensivity to Market Risk
B13: Higher is Better | C13: Higher is Better | D13: Higher is Better | E13: Lower is Better | F13: Higher is Better | G13: Higher is Better | H13: Higher is Better | I13: Lower is better
B14: Return on Assets | C14: Income Spread/Total Asset | D14: Operating Profit /Total Asset | E14: Operating expenses by Net Inc | F14: Cash Asset/Total Asset | G14: G-Sec/Total Asset | H14: Liquid Asset/ Total Asset Ratio | I14: Beta (5-yr monthly) Source: Thomson Reuters
A15: HDFC Bank | B15: 0.0164 | C15: 0.03769 | D15: 0.0307 | E15: 1.3 | F15: 0.1 | G15: 0.18 | H15: 0.16 | I15: 0.99
A16: Yes Bank | B16: 0.0135 | C16: 0.02476 | D16: 0.02 | E16: 1.23 | F16: 0.04 | G16: 0.16 | H16: 0.12 | I16: 1.88
A17: ICICI Bank | B17: 0.0077 | C17: 0.02619 | D17: 0.02 | E17: 2.32 | F17: 0.04 | G17: 0.16 | H17: 0.15 | I17: 1.47
A18: Axis Bank | B18: 0.0004 | C18: 0.02693 | D18: 0.02 | E18: 50.75 | F18: 0.05 | G18: 0.15 | H18: 0.1 | I18: 1.45
A19: SBI | B19: -0.0019 | C19: 0.02167 | D19: 0.02 | E19: -9.16 | F19: 0.04 | G19: 0.25 | H19: 0.07 | I19: 1.68
A20: Weights | B20: 0.0025 | C20: 0.25 | D20: 0.25 | E20: 0.0025 | F20: 0.25 | G20: 0.25 | H20: 0.5 | I20: 1
A21: Composite Weights | B21: 0.2 | F21: 0.1 | I21: 0.1
A23: Notes: SBI = State Bank of India; ROA = Return on Assets.
A24: Source: Created by case authors.

Sheet DCF Valuation
A4: Tax Rate (t) | C4: 0.345
A6: WACC Calculation
A7: Market Values
A8: Debt (Wd) | C8: ='Workings '!B27 -> 1231049700000
A9: Equity (We) | C9: ='Workings '!B26 -> 4.9973653e+12
A10: Risk-Free-Rate | B10: ='Workings '!B14 -> 0.0775
A11: Beta (For Next 15 Years) | B11: ='Workings '!B18 -> 1.05
A12: Beta (Terminal Value) | B12: ='Workings '!B19 -> 1
A13: Market Risk Premium | B13: ='Workings '!B13 -> 0.0787
A14: Cost of Equity (Ke) (For Next 15 Years) | C14: ='Workings '!B22 -> 0.160135
A15: Cost of Equity (Ke) (Terminal Value) | C15: ='Workings '!B24 -> 0.1562
A16: Cost of Debt Before-Tax | C16: ='Workings '!B23 -> 0.0775
A17: Cost of Debt After-Tax (Kd) | C17: =C16*(1-C4) -> 0.0507625
A18: WACC(Kc) (For Next 15 Years) | C18: =((C9*C14)+(C8*C16))/(C8+C9) -> 0.14380215
A19: WACC(Kc) (Terminal) | C19: =((C9*C15)+(C8*C16))/(C8+C9) -> 0.1406449
A23: Growth rate
A24: Growth ( Next Five Years) | C24: 0.1262
A25: Growth ( 10 Years Thereafter) | C25: 0.1
A26: Growth (Terminal) | C26: 0.06
A28: FCF for 2018 | C28: 2017 | D28: 2018
A30: Free Cash Flow (FCF)
A31: PBT | D31: ='Workings '!C2 -> 266973200000
A32: ='Workings '!A3 -> Capital Expenditure
A33: Fixed Assets | C33: ='Workings '!B4 -> 36267379000 | D33: ='Workings '!B5 -> 36072045000
A34: ='Workings '!A6 -> Depreciation | D34: ='Workings '!C6 -> 9063418000
A35: ='Workings '!A7 -> Changes in Working Capital | C35: ='Workings '!B8 -> 1109123843000 | D35: ='Workings '!B9 -> 1028776785000
A36: FCF | D36: =(D31*(1-C4))-((D33-C33)-D34)-(D35-C35) -> 264473256000
A38: Present Value of Forecasted FCF for 2019 - 2023 | C38: 2019 | D38: 2020 | E38: 2021 | F38: 2022 | G38: 2023
A39: N | C39: 1 | D39: 2 | E39: 3 | F39: 4 | G39: 5
A40: PV of FCF | C40: =($D$36*POWER((1+$C$24),C39))/POWER((1+$C$18),C39) -> 2.6040324e+11 | D40: =($D$36*POWER((1+$C$24),D39))/POWER((1+$C$18),D39) -> 2.5639585e+11 | E40: =($D$36*POWER((1+$C$24),E39))/POWER((1+$C$18),E39) -> 2.5245014e+11 | F40: =($D$36*POWER((1+$C$24),F39))/POWER((1+$C$18),F39) -> 2.4856514e+11 | G40: =($D$36*POWER((1+$C$24),G39))/POWER((1+$C$18),G39) -> 2.4473994e+11
A42: Present Value of Forecasted FCF for 2024 - 2034 | C42: 2024 | D42: 2025 | E42: 2026 | F42: 2027 | G42: 2028 | H42: 2029 | I42: 2030 | J42: 2031 | K42: 2032 | L42: 2033
A43: N | C43: =$G$39+1 -> 6 | D43: =C43+1 -> 7 | E43: =D43+1 -> 8 | F43: =E43+1 -> 9 | G43: =F43+1 -> 10 | H43: =G43+1 -> 11 | I43: =H43+1 -> 12 | J43: =I43+1 -> 13 | K43: =J43+1 -> 14 | L43: =K43+1 -> 15
A44: =A40 -> PV of FCF | C44: =($D$36*POWER((1+$C$25),C43))/POWER((1+$C$18),C43) -> 2.0923408e+11 | D44: =($D$36*POWER((1+$C$25),D43))/POWER((1+$C$18),D43) -> 2.0122142e+11 | E44: =($D$36*POWER((1+$C$25),E43))/POWER((1+$C$18),E43) -> 1.935156e+11 | F44: =($D$36*POWER((1+$C$25),F43))/POWER((1+$C$18),F43) -> 1.8610488e+11 | G44: =($D$36*POWER((1+$C$25),G43))/POWER((1+$C$18),G43) -> 1.7897796e+11 | H44: =($D$36*POWER((1+$C$25),H43))/POWER((1+$C$18),H43) -> 1.7212396e+11 | I44: =($D$36*POWER((1+$C$25),I43))/POWER((1+$C$18),I43) -> 1.6553243e+11 | J44: =($D$36*POWER((1+$C$25),J43))/POWER((1+$C$18),J43) -> 1.5919333e+11 | ... L44: =($D$36*POWER((1+$C$25),L43))/POWER((1+$C$18),L43) -> 1.4723411e+11
A46: Present Value of Forecasted FCF for 2024 - 2034
A47: PV of Terminal Value | C47: =(($D$36*POWER((1+$C$24),L43)*(1+C26))/(C15-C16))/POWER((1+C18),L43) -> 2.8228132e+12
A50: Intrinsic Value Per Share
A51: ='Workings '!A12 -> Cash | C51: ='Workings '!C12 -> 1229150827000
A52: ='Workings '!A26 -> Market Value of Equity | C52: ='Workings '!B26 -> 4.9973653e+12
A53: ='Workings '!A27 -> Book Value of Debt | C53: ='Workings '!B27 -> 1231049700000
A54: ='Workings '!A25 -> Number of Shares Outstanding | C54: ='Workings '!B25 -> 2595090267
...

Sheet Workings 
A1: Particular | C1: Amount (in ₹ ) | E1: Current Assets and Liabilities
A2: PBT | C2: 266973200000 | G2: 2017 | H2: 2018
A3: Capital Expenditure | C3: =B5-B4 -> -195334000 | E3: Investment | F3: CA | G3: 2144633366000 | H3: 2422002416000
A4: :- Fixed assets (2017) | B4: 36267379000 | E4: Advances | F4: CA | G4: 5545682021000 | H4: 6583330908000
A5: :- Fixed assets (2018) | B5: 36072045000 | E5: Deposits | F5: CL | G5: 6436396563000 | H5: 7887706396000
A6: Depreciation | C6: 9063418000 | E6: Other Assests | F6: CA | G6: 422298200000 | H6: 368787038000
A7: Changes in Working Capital | C7: =B9-B8 -> -80347058000 | E7: Other Liabilities and Provisions | F7: CL | G7: 567093181000 | H7: 457637181000
A8: Net Current Assests (2017) | B8: =G8 -> 1109123843000 | E8: Net Current Assests | G8: =(G3+G4+G6)-(G5+G7) -> 1109123843000 | H8: =(H3+H4+H6)-(H5+H7) -> 1028776785000
A9: Net Current Assests (2018) | B9: =H8 -> 1028776785000
A12: Cash | C12: =1046704730000+182446097000 -> 1229150827000
A13: Risk Premium | B13: 0.0787
A14: RF | B14: 0.0775
A15: Growth (Next Five Years) | B15: 0.1262
A16: Growth (10 Years Thereafter) | B16: 0.1
A17: Growth (Terminal) | B17: 0.06
A18: Beta (Next 15 years) | B18: 1.05
A19: Beta (Terminal) | B19: 1
A20: WACC (Next 15 Years) | C20: =((B22*B26)+(B23*B27))/(B26+B27) -> 0.14380215
A21: WACC (Terminal) | C21: =((B24*B26)+(B23*B27))/(B26+B27) -> 0.1406449
A22: Cost of Equity (Next 15 years) | B22: =B14+B18*B13 -> 0.160135
A23: Cost of Debt | B23: 0.0775
A24: Cost of Equity (Terminal Case) | B24: =B14+B19*B13 -> 0.1562
A25: Number of Shares Outstanding | B25: 2595090267
A26: Market Value of Equity | B26: =1925.7*2595090267 -> 4.9973653e+12
A27: Book Value of Debt | B27: 1231049700000
A28: Market Price on September 24, 2018 | B28: 1925.7
A31: Notes: PBT = Profit before Tax; RF = Risk-free rate; WACC = weightage average cost of capital; CA = current assets; CL = current liabilities.
A32: Source: HDFC Bank Ltd., Experiential Leadership: Enabling Personalized Customer Journeys through Technology, Annual Report 2017–18, accessed September 30, 2018, www.hdfcbank.com/htdocs/common/pdf/corporate/Annual_Report_2017_18.pdf

Sheet Exhibit 8
A1: EXHIBIT 8: HDFC BANK KEY FINANCIAL PARAMETERS, 2013-2018
A2: Financial Year | B2: 2017–18 | C2: 2016–17 | D2: 2015–16 | E2: 2014–15 | F2: 2013–14
A3: Advances (in ₹ million) | B3: 65833.3 | C3: 55456.8 | D3: 46459.4 | E3: 36549.5 | F3: 30300
A4: Deposits (in ₹ million) | B4: 78877.1 | C4: 64364 | D4: 54642.4 | E4: 45079.6 | F4: 36733.7
A5: Net Interest Income (in ₹ million) | B5: 4009.486 | C5: 3313.922 | D5: 2759.152 | E5: 2239.568 | F5: 1848.263
A6: Current Account Saving Account (%) | B6: 43.5 | C6: 48 | D6: 43 | E6: 44 | F6: 44.8
A7: Return on Assets (%) | B7: 1.64 | C7: 1.68 | D7: 1.73 | E7: 1.73 | F7: 1.72
A8: Return on Equity (%) | B8: 16.45 | C8: 16.26 | D8: 16.91 | E8: 16.47 | F8: 19.5
A9: Net Non-Performing Assets (%) | B9: 0.4 | C9: 0.33 | D9: 0.28 | E9: 0.25 | F9: 0.27
A10: Number of Automated Teller Machines | B10: 12635 | C10: 12260 | D10: 12000 | E10: 11766 | F10: 11256
A11: Number of Branches | B11: 4787 | C11: 4715 | D11: 4520 | E11: 4014 | F11: 3403
A13: Source: HDFC Bank Ltd., Investor Presentation, accessed September 30, 2018, www.hdfcbank.com/assets/pdf/Investor_Presentation.pdf.

Sheet Exhibit 9
C1: EXHIBIT 9: HDFC BANK INCOME STATEMENT, 2013-2018 (IN ₹ MILLION)
B2: Date
B3: Number of Months
B4: 43160 | C4: 42795 | D4: 42430 | E4: 42064 | F4: 41699
B5: 12 | C5: 12 | D5: 12 | E5: 12
A6: I. INCOME
A7: Interest Earned | B7: 8024.136 | C7: 6930.596 | D7: 6022.145 | E7: 4846.99 | F7: 4113.553
A8: Other Income | B8: 1522.03 | C8: 1229.65 | D8: 1075.172 | E8: 899.635 | F8: 791.964
A9: Total Income | B9: 9546.166 | C9: 8160.246 | D9: 7097.317 | E9: 5746.626 | F9: 4905.518
A10: II. EXPENDITURE
A11: Interest Expended | B11: 4014.649 | C11: 3616.673 | D11: 3262.993 | E11: 2607.424 | F11: 2265.29
A12: Operating Expenses | B12: 2269.038 | C12: 1970.334 | D12: 1697.97 | E12: 1398.754 | F12: 1204.22
A13: Provisions and Contingencies | B13: 5927.49 | C13: 3593.31 | D13: 2725.61 | E13: 2075.01 | F13: 1587.27
A14: Profit before Tax | B14: 2669.73 | C14: 2213.907 | D14: 1863.792 | E14: 1532.947 | F14: 1277.281
A15: Taxes | B15: 921.057 | C15: 758.943 | D15: 634.171 | E15: 511.355 | F15: 429.443
A16: Total | B16: 7797.493 | C16: 6705.282 | D16: 5867.696 | E16: 4725.034 | F16: 4057.68
A17: III. PROFIT AND LOSS
A18: Profit after Tax | B18: 1748.673 | C18: 1454.964 | D18: 1229.621 | E18: 1021.592 | F18: 847.838
A19: Extra Items
A20: Profit Brought Forward | B20: 3266.894 | C20: 2352.769 | D20: 1862.779 | E20: 1465.415 | F20: 1113.218
A21: Adjustments to Profit and Loss
A22: Total Profit and Loss | B22: 5015.567 | C22: 3807.733 | D22: 3092.401 | E22: 2487.007 | F22: 1961.056
A23: Equity Dividend (%) | B23: 650 | C23: 550 | D23: 475 | E23: 400 | F23: 342.5
A24: Earnings per Share | B24: 67.38 | C24: 56.78 | D24: 48.64 | E24: 40.76 | F24: 35.34
A25: Adjusted Earnings per Share | B25: 67.38 | C25: 56.78 | D25: 48.64 | E25: 40.76 | F25: 35.34
A27: Source: HDFC Bank Ltd., Investor Presentation, accessed September 30, 2018, www.hdfcbank.com/assets/pdf/Investor_Presentation.pdf.

Sheet Exhibit 10
A1: EXHIBIT 10: HDFC BANK BALANCE SHEET, 2013-2018 (IN ₹ MILLION)
B2: 43160 | C2: 42795 | D2: 42430 | E2: 42064 | F2: 41699
A3: SOURCES OF FUNDS
A4: Share Capital | B4: 51.902 | C4: 51.251 | D4: 50.564 | E4: 50.13 | F4: 47.981
A5: Share Warrants and Outstanding shares | B5: 0 | C5: 0 | D5: 0 | E5: 0 | F5: 0
A6: Total Reserves | B6: 10577.598 | C6: 8894.983 | D6: 7217.213 | E6: 6150.812 | F6: 4299.882
A7: Deposits | B7: 78877.064 | C7: 64363.966 | D7: 54642.419 | E7: 45079.564 | F7: 36733.748
A8: Borrowings | B8: 12310.497 | C8: 7402.887 | D8: 8496.898 | E8: 4521.356 | F8: 3943.899
A9: Other Liabilities and Provisions | B9: 4576.372 | C9: 5670.932 | D9: 3672.513 | E9: 3248.446 | F9: 4134.44
A10: Total Liabilities | B10: 106393.43 | C10: 86384.019 | D10: 74079.607 | E10: 59050.307 | F10: 49159.95
A11: APPLICATION OF FUNDS
A12: Cash and Balance with Reserve Bank of India | B12: 10467.047 | C12: 3789.688 | D12: 3005.831 | E12: 2751.045 | F12: 2534.563
A13: Balances with Banks and Money at Call | B13: 1824.461 | C13: 1105.522 | D13: 886.053 | E13: 882.1 | F13: 1423.801
A14: Investments | B14: 24220.024 | C14: 21446.334 | D14: 19583.628 | E14: 15164.175 | F14: 12095.107
A15: Advances | B15: 65833.309 | C15: 55456.82 | D15: 46459.396 | E15: 36549.503 | F15: 30300.027
A16: Gross Block | B16: 1093.258 | C16: 1015.766 | D16: 925.262 | E16: 846.33 | F16: 770.582
A17: Less: Accumulated Depreciation | B17: 728.113 | C17: 648.668 | D17: 586.522 | E17: 529.732 | F17: 472.165
A18: Less: Impairment of Assets
A19: Net Block | B19: 365.145 | C19: 367.098 | D19: 338.74 | E19: 316.598 | F19: 298.4.6
A20: Lease Adjustment | B20: -4.425 | C20: -4.425 | D20: -4.425 | E20: -4.425 | F20: -4.425
A21: Capital Work in Progress
A22: Other Assets | B22: 3687.87 | C22: 4222.982 | D22: 3810.384 | E22: 3391.31 | F22: 2512.46
A23: Total Assets | B23: 106393.43 | C23: 86384.019 | D23: 74079.607 | E23: 59050.307 | F23: 49159.95
A24: Contingent Liabilities | B24: 87548.823 | C24: 81786.959 | D24: 85331.811 | E24: 97523.395 | F24: 72315.491
A25: Bills for Collection | B25: 4275.383 | C25: 3084.804 | D25: 2349 | E25: 2230.493 | F25: 2094.306
A26: Book Value | B26: 40.96 | C26: 34.912 | D26: 28.747 | E26: 24.739 | F26: 18.123
A27: Adjusted Book Value | B27: 40.96 | C27: 34.912 | D27: 28.747 | E27: 24.739 | F27: 18.123
A29: Source: HDFC Bank Ltd., Investor Presentation, accessed September 30, 2018, www.hdfcbank.com/assets/pdf/Investor_Presentation.pdf.

Sheet Exhibit TN-2
A1: EXHIBIT TN-2: LONG-TERM GROWTH RATE CALCULATION
B2: 2019
A3: Retention Ratio (1 - Payout Ratio) | B3: 0.7674
A4: Return on Equity | B4: 0.1645
A5: Estimated Long-Term Growth Rate | B5: 0.1262
A7: Source: HDFC Bank Ltd., Experiential Leadership: Enabling Personalized Customer Journeys through Technology, Annual Report 2017–18, accessed September 30, 2018, www.hdfcbank.com/htdocs/common/pdf/corporate/Annual_Report_2017_18.pdf
